I'm sorry, but an uncaught exception occurred.

While running game code:
  File "game/script.rpy", line 75, in script call
    call scene13_end # Разговор обо сне с другом
  File "game/script.rpy", line 905, in script
    maks 'Ты видел, что в УрФУ проходит День открытых дверей, пойдём?'
Exception: Sayer 'maks' is not defined.

-- Full Traceback ------------------------------------------------------------

Full traceback:
  File "game/script.rpy", line 75, in script call
    call scene13_end # Разговор обо сне с другом
  File "game/script.rpy", line 905, in script
    maks 'Ты видел, что в УрФУ проходит День открытых дверей, пойдём?'
  File "C:\Users\alexe\OneDrive\Рабочий стол\Ren'Py\renpy-8.1.3-sdk\renpy\ast.py", line 890, in execute
    who = eval_who(self.who, self.who_fast)
  File "C:\Users\alexe\OneDrive\Рабочий стол\Ren'Py\renpy-8.1.3-sdk\renpy\ast.py", line 783, in eval_who
    raise Exception("Sayer '%s' is not defined." % who)
Exception: Sayer 'maks' is not defined.

Windows-10-10.0.22631 AMD64
Ren'Py 8.1.3.23091805
IT princess_name_game 1.0
Sat Dec  9 22:27:14 2023
