I'm sorry, but an uncaught exception occurred.

While running game code:
  File "game/script.rpy", line 66, in script call
    call scene9_gnoms from _call_scene9_gnoms # Встреча с гномами
  File "game/script.rpy", line 474, in script
    with moveinbottm
  File "game/script.rpy", line 474, in <module>
    with moveinbottm
NameError: name 'moveinbottm' is not defined

-- Full Traceback ------------------------------------------------------------

Full traceback:
  File "game/script.rpy", line 66, in script call
    call scene9_gnoms from _call_scene9_gnoms # Встреча с гномами
  File "game/script.rpy", line 474, in script
    with moveinbottm
  File "C:\Users\alexe\OneDrive\Рабочий стол\Ren'Py\renpy-8.1.3-sdk\renpy\ast.py", line 1671, in execute
    trans = renpy.python.py_eval(self.expr)
  File "C:\Users\alexe\OneDrive\Рабочий стол\Ren'Py\renpy-8.1.3-sdk\renpy\python.py", line 1153, in py_eval
    return py_eval_bytecode(code, globals, locals)
  File "C:\Users\alexe\OneDrive\Рабочий стол\Ren'Py\renpy-8.1.3-sdk\renpy\python.py", line 1146, in py_eval_bytecode
    return eval(bytecode, globals, locals)
  File "game/script.rpy", line 474, in <module>
    with moveinbottm
NameError: name 'moveinbottm' is not defined

Windows-10-10.0.22631 AMD64
Ren'Py 8.1.3.23091805
IT princess_name_game 3.0
Mon Dec 18 23:07:16 2023
